30/08/22 (18:55:25) | ERROR: <urlopen error [Errno 8] nodename nor servname provided, or not known>
Traceback (most recent call last):
  File "/usr/local/Cellar/python@3.10/3.10.6_1/Frameworks/Python.framework/Versions/3.10/lib/python3.10/urllib/request.py", line 1348, in do_open
    h.request(req.get_method(), req.selector, req.data, headers,
  File "/usr/local/Cellar/python@3.10/3.10.6_1/Frameworks/Python.framework/Versions/3.10/lib/python3.10/http/client.py", line 1282, in request
    self._send_request(method, url, body, headers, encode_chunked)
  File "/usr/local/Cellar/python@3.10/3.10.6_1/Frameworks/Python.framework/Versions/3.10/lib/python3.10/http/client.py", line 1328, in _send_request
    self.endheaders(body, encode_chunked=encode_chunked)
  File "/usr/local/Cellar/python@3.10/3.10.6_1/Frameworks/Python.framework/Versions/3.10/lib/python3.10/http/client.py", line 1277, in endheaders
    self._send_output(message_body, encode_chunked=encode_chunked)
  File "/usr/local/Cellar/python@3.10/3.10.6_1/Frameworks/Python.framework/Versions/3.10/lib/python3.10/http/client.py", line 1037, in _send_output
    self.send(msg)
  File "/usr/local/Cellar/python@3.10/3.10.6_1/Frameworks/Python.framework/Versions/3.10/lib/python3.10/http/client.py", line 975, in send
    self.connect()
  File "/usr/local/Cellar/python@3.10/3.10.6_1/Frameworks/Python.framework/Versions/3.10/lib/python3.10/http/client.py", line 1447, in connect
    super().connect()
  File "/usr/local/Cellar/python@3.10/3.10.6_1/Frameworks/Python.framework/Versions/3.10/lib/python3.10/http/client.py", line 941, in connect
    self.sock = self._create_connection(
  File "/usr/local/Cellar/python@3.10/3.10.6_1/Frameworks/Python.framework/Versions/3.10/lib/python3.10/socket.py", line 824, in create_connection
    for res in getaddrinfo(host, port, 0, SOCK_STREAM):
  File "/usr/local/Cellar/python@3.10/3.10.6_1/Frameworks/Python.framework/Versions/3.10/lib/python3.10/socket.py", line 955, in getaddrinfo
    for res in _socket.getaddrinfo(host, port, family, type, proto, flags):
socket.gaierror: [Errno 8] nodename nor servname provided, or not known

During handling of the above exception, another exception occurred:

Traceback (most recent call last):
  File "/usr/local/bin/bpytop", line 5029, in _checker
    with urllib.request.urlopen("https://github.com/aristocratos/bpytop/raw/master/bpytop.py", timeout=5) as source: # type: ignore
  File "/usr/local/Cellar/python@3.10/3.10.6_1/Frameworks/Python.framework/Versions/3.10/lib/python3.10/urllib/request.py", line 216, in urlopen
    return opener.open(url, data, timeout)
  File "/usr/local/Cellar/python@3.10/3.10.6_1/Frameworks/Python.framework/Versions/3.10/lib/python3.10/urllib/request.py", line 519, in open
    response = self._open(req, data)
  File "/usr/local/Cellar/python@3.10/3.10.6_1/Frameworks/Python.framework/Versions/3.10/lib/python3.10/urllib/request.py", line 536, in _open
    result = self._call_chain(self.handle_open, protocol, protocol +
  File "/usr/local/Cellar/python@3.10/3.10.6_1/Frameworks/Python.framework/Versions/3.10/lib/python3.10/urllib/request.py", line 496, in _call_chain
    result = func(*args)
  File "/usr/local/Cellar/python@3.10/3.10.6_1/Frameworks/Python.framework/Versions/3.10/lib/python3.10/urllib/request.py", line 1391, in https_open
    return self.do_open(http.client.HTTPSConnection, req,
  File "/usr/local/Cellar/python@3.10/3.10.6_1/Frameworks/Python.framework/Versions/3.10/lib/python3.10/urllib/request.py", line 1351, in do_open
    raise URLError(err)
urllib.error.URLError: <urlopen error [Errno 8] nodename nor servname provided, or not known>
07/11/22 (09:21:18) | ERROR: Exception while getting cpu frequency!
07/11/22 (09:21:18) | ERROR: [Errno 2] No such file or directory (originated from sysctlbyname('hw.cpufrequency'))
Traceback (most recent call last):
  File "/opt/homebrew/bin/bpytop", line 3080, in _collect
    if CONFIG.show_cpu_freq and hasattr(psutil.cpu_freq(), "current"):
  File "/opt/homebrew/Cellar/bpytop/1.0.68/libexec/lib/python3.10/site-packages/psutil/__init__.py", line 1859, in cpu_freq
    ret = _psplatform.cpu_freq()
  File "/opt/homebrew/Cellar/bpytop/1.0.68/libexec/lib/python3.10/site-packages/psutil/_psosx.py", line 180, in cpu_freq
    curr, min_, max_ = cext.cpu_freq()
FileNotFoundError: [Errno 2] No such file or directory (originated from sysctlbyname('hw.cpufrequency'))
16/11/22 (10:18:13) | ERROR: Exception while getting cpu frequency!
16/11/22 (10:18:13) | ERROR: [Errno 2] No such file or directory (originated from sysctlbyname('hw.cpufrequency'))
Traceback (most recent call last):
  File "/opt/homebrew/bin/bpytop", line 3080, in _collect
    if CONFIG.show_cpu_freq and hasattr(psutil.cpu_freq(), "current"):
  File "/opt/homebrew/Cellar/bpytop/1.0.68/libexec/lib/python3.10/site-packages/psutil/__init__.py", line 1859, in cpu_freq
    ret = _psplatform.cpu_freq()
  File "/opt/homebrew/Cellar/bpytop/1.0.68/libexec/lib/python3.10/site-packages/psutil/_psosx.py", line 180, in cpu_freq
    curr, min_, max_ = cext.cpu_freq()
FileNotFoundError: [Errno 2] No such file or directory (originated from sysctlbyname('hw.cpufrequency'))
