30/08/22 (18:55:25) | ERROR: <urlopen error [Errno 8] nodename nor servname provided, or not known>
Traceback (most recent call last):
  File "/usr/local/Cellar/python@3.10/3.10.6_1/Frameworks/Python.framework/Versions/3.10/lib/python3.10/urllib/request.py", line 1348, in do_open
    h.request(req.get_method(), req.selector, req.data, headers,
  File "/usr/local/Cellar/python@3.10/3.10.6_1/Frameworks/Python.framework/Versions/3.10/lib/python3.10/http/client.py", line 1282, in request
    self._send_request(method, url, body, headers, encode_chunked)
  File "/usr/local/Cellar/python@3.10/3.10.6_1/Frameworks/Python.framework/Versions/3.10/lib/python3.10/http/client.py", line 1328, in _send_request
    self.endheaders(body, encode_chunked=encode_chunked)
  File "/usr/local/Cellar/python@3.10/3.10.6_1/Frameworks/Python.framework/Versions/3.10/lib/python3.10/http/client.py", line 1277, in endheaders
    self._send_output(message_body, encode_chunked=encode_chunked)
  File "/usr/local/Cellar/python@3.10/3.10.6_1/Frameworks/Python.framework/Versions/3.10/lib/python3.10/http/client.py", line 1037, in _send_output
    self.send(msg)
  File "/usr/local/Cellar/python@3.10/3.10.6_1/Frameworks/Python.framework/Versions/3.10/lib/python3.10/http/client.py", line 975, in send
    self.connect()
  File "/usr/local/Cellar/python@3.10/3.10.6_1/Frameworks/Python.framework/Versions/3.10/lib/python3.10/http/client.py", line 1447, in connect
    super().connect()
  File "/usr/local/Cellar/python@3.10/3.10.6_1/Frameworks/Python.framework/Versions/3.10/lib/python3.10/http/client.py", line 941, in connect
    self.sock = self._create_connection(
  File "/usr/local/Cellar/python@3.10/3.10.6_1/Frameworks/Python.framework/Versions/3.10/lib/python3.10/socket.py", line 824, in create_connection
    for res in getaddrinfo(host, port, 0, SOCK_STREAM):
  File "/usr/local/Cellar/python@3.10/3.10.6_1/Frameworks/Python.framework/Versions/3.10/lib/python3.10/socket.py", line 955, in getaddrinfo
    for res in _socket.getaddrinfo(host, port, family, type, proto, flags):
socket.gaierror: [Errno 8] nodename nor servname provided, or not known

During handling of the above exception, another exception occurred:

Traceback (most recent call last):
  File "/usr/local/bin/bpytop", line 5029, in _checker
    with urllib.request.urlopen("https://github.com/aristocratos/bpytop/raw/master/bpytop.py", timeout=5) as source: # type: ignore
  File "/usr/local/Cellar/python@3.10/3.10.6_1/Frameworks/Python.framework/Versions/3.10/lib/python3.10/urllib/request.py", line 216, in urlopen
    return opener.open(url, data, timeout)
  File "/usr/local/Cellar/python@3.10/3.10.6_1/Frameworks/Python.framework/Versions/3.10/lib/python3.10/urllib/request.py", line 519, in open
    response = self._open(req, data)
  File "/usr/local/Cellar/python@3.10/3.10.6_1/Frameworks/Python.framework/Versions/3.10/lib/python3.10/urllib/request.py", line 536, in _open
    result = self._call_chain(self.handle_open, protocol, protocol +
  File "/usr/local/Cellar/python@3.10/3.10.6_1/Frameworks/Python.framework/Versions/3.10/lib/python3.10/urllib/request.py", line 496, in _call_chain
    result = func(*args)
  File "/usr/local/Cellar/python@3.10/3.10.6_1/Frameworks/Python.framework/Versions/3.10/lib/python3.10/urllib/request.py", line 1391, in https_open
    return self.do_open(http.client.HTTPSConnection, req,
  File "/usr/local/Cellar/python@3.10/3.10.6_1/Frameworks/Python.framework/Versions/3.10/lib/python3.10/urllib/request.py", line 1351, in do_open
    raise URLError(err)
urllib.error.URLError: <urlopen error [Errno 8] nodename nor servname provided, or not known>
07/11/22 (09:21:18) | ERROR: Exception while getting cpu frequency!
07/11/22 (09:21:18) | ERROR: [Errno 2] No such file or directory (originated from sysctlbyname('hw.cpufrequency'))
Traceback (most recent call last):
  File "/opt/homebrew/bin/bpytop", line 3080, in _collect
    if CONFIG.show_cpu_freq and hasattr(psutil.cpu_freq(), "current"):
  File "/opt/homebrew/Cellar/bpytop/1.0.68/libexec/lib/python3.10/site-packages/psutil/__init__.py", line 1859, in cpu_freq
    ret = _psplatform.cpu_freq()
  File "/opt/homebrew/Cellar/bpytop/1.0.68/libexec/lib/python3.10/site-packages/psutil/_psosx.py", line 180, in cpu_freq
    curr, min_, max_ = cext.cpu_freq()
FileNotFoundError: [Errno 2] No such file or directory (originated from sysctlbyname('hw.cpufrequency'))
16/11/22 (10:18:13) | ERROR: Exception while getting cpu frequency!
16/11/22 (10:18:13) | ERROR: [Errno 2] No such file or directory (originated from sysctlbyname('hw.cpufrequency'))
Traceback (most recent call last):
  File "/opt/homebrew/bin/bpytop", line 3080, in _collect
    if CONFIG.show_cpu_freq and hasattr(psutil.cpu_freq(), "current"):
  File "/opt/homebrew/Cellar/bpytop/1.0.68/libexec/lib/python3.10/site-packages/psutil/__init__.py", line 1859, in cpu_freq
    ret = _psplatform.cpu_freq()
  File "/opt/homebrew/Cellar/bpytop/1.0.68/libexec/lib/python3.10/site-packages/psutil/_psosx.py", line 180, in cpu_freq
    curr, min_, max_ = cext.cpu_freq()
FileNotFoundError: [Errno 2] No such file or directory (originated from sysctlbyname('hw.cpufrequency'))
30/01/23 (23:11:24) | ERROR: Exception while getting cpu frequency!
30/01/23 (23:11:24) | ERROR: [Errno 2] No such file or directory (originated from sysctlbyname('hw.cpufrequency'))
Traceback (most recent call last):
  File "/opt/homebrew/bin/bpytop", line 3080, in _collect
    if CONFIG.show_cpu_freq and hasattr(psutil.cpu_freq(), "current"):
  File "/opt/homebrew/Cellar/bpytop/1.0.68/libexec/lib/python3.10/site-packages/psutil/__init__.py", line 1859, in cpu_freq
    ret = _psplatform.cpu_freq()
  File "/opt/homebrew/Cellar/bpytop/1.0.68/libexec/lib/python3.10/site-packages/psutil/_psosx.py", line 180, in cpu_freq
    curr, min_, max_ = cext.cpu_freq()
FileNotFoundError: [Errno 2] No such file or directory (originated from sysctlbyname('hw.cpufrequency'))
24/02/23 (18:46:11) | ERROR: Exception while getting cpu frequency!
24/02/23 (18:46:11) | ERROR: [Errno 2] No such file or directory (originated from sysctlbyname('hw.cpufrequency'))
Traceback (most recent call last):
  File "/opt/homebrew/bin/bpytop", line 3080, in _collect
    if CONFIG.show_cpu_freq and hasattr(psutil.cpu_freq(), "current"):
  File "/opt/homebrew/Cellar/bpytop/1.0.68/libexec/lib/python3.10/site-packages/psutil/__init__.py", line 1859, in cpu_freq
    ret = _psplatform.cpu_freq()
  File "/opt/homebrew/Cellar/bpytop/1.0.68/libexec/lib/python3.10/site-packages/psutil/_psosx.py", line 180, in cpu_freq
    curr, min_, max_ = cext.cpu_freq()
FileNotFoundError: [Errno 2] No such file or directory (originated from sysctlbyname('hw.cpufrequency'))
24/02/23 (18:46:20) | ERROR: Data collection thread failed with exception: [Errno 5] Input/output error
Traceback (most recent call last):
  File "/opt/homebrew/bin/bpytop", line 2965, in _runner
    else: Draw.out()
  File "/opt/homebrew/bin/bpytop", line 1091, in out
    cls.now(out)
  File "/opt/homebrew/bin/bpytop", line 1039, in now
    print(*args, sep="", end="", flush=True)
OSError: [Errno 5] Input/output error
11/07/23 (11:01:02) | ERROR: Exception while getting cpu frequency!
11/07/23 (11:01:02) | ERROR: [Errno 2] No such file or directory (originated from sysctlbyname('hw.cpufrequency'))
Traceback (most recent call last):
  File "/opt/homebrew/bin/bpytop", line 3080, in _collect
    if CONFIG.show_cpu_freq and hasattr(psutil.cpu_freq(), "current"):
  File "/opt/homebrew/Cellar/bpytop/1.0.68/libexec/lib/python3.10/site-packages/psutil/__init__.py", line 1859, in cpu_freq
    ret = _psplatform.cpu_freq()
  File "/opt/homebrew/Cellar/bpytop/1.0.68/libexec/lib/python3.10/site-packages/psutil/_psosx.py", line 180, in cpu_freq
    curr, min_, max_ = cext.cpu_freq()
FileNotFoundError: [Errno 2] No such file or directory (originated from sysctlbyname('hw.cpufrequency'))
12/08/23 (17:25:22) | ERROR: Exception while getting cpu frequency!
12/08/23 (17:25:22) | ERROR: [Errno 2] No such file or directory (originated from sysctlbyname('hw.cpufrequency'))
Traceback (most recent call last):
  File "/opt/homebrew/bin/bpytop", line 3080, in _collect
    if CONFIG.show_cpu_freq and hasattr(psutil.cpu_freq(), "current"):
  File "/opt/homebrew/Cellar/bpytop/1.0.68/libexec/lib/python3.10/site-packages/psutil/__init__.py", line 1859, in cpu_freq
    ret = _psplatform.cpu_freq()
  File "/opt/homebrew/Cellar/bpytop/1.0.68/libexec/lib/python3.10/site-packages/psutil/_psosx.py", line 180, in cpu_freq
    curr, min_, max_ = cext.cpu_freq()
FileNotFoundError: [Errno 2] No such file or directory (originated from sysctlbyname('hw.cpufrequency'))
01/09/23 (15:40:24) | ERROR: Exception while getting cpu frequency!
01/09/23 (15:40:24) | ERROR: [Errno 2] No such file or directory (originated from sysctlbyname('hw.cpufrequency'))
Traceback (most recent call last):
  File "/opt/homebrew/bin/bpytop", line 3080, in _collect
    if CONFIG.show_cpu_freq and hasattr(psutil.cpu_freq(), "current"):
  File "/opt/homebrew/Cellar/bpytop/1.0.68/libexec/lib/python3.10/site-packages/psutil/__init__.py", line 1859, in cpu_freq
    ret = _psplatform.cpu_freq()
  File "/opt/homebrew/Cellar/bpytop/1.0.68/libexec/lib/python3.10/site-packages/psutil/_psosx.py", line 180, in cpu_freq
    curr, min_, max_ = cext.cpu_freq()
FileNotFoundError: [Errno 2] No such file or directory (originated from sysctlbyname('hw.cpufrequency'))
05/10/23 (10:49:25) | ERROR: Exception while getting cpu frequency!
05/10/23 (10:49:25) | ERROR: [Errno 2] No such file or directory (originated from sysctlbyname('hw.cpufrequency'))
Traceback (most recent call last):
  File "/opt/homebrew/bin/bpytop", line 3080, in _collect
    if CONFIG.show_cpu_freq and hasattr(psutil.cpu_freq(), "current"):
  File "/opt/homebrew/Cellar/bpytop/1.0.68/libexec/lib/python3.10/site-packages/psutil/__init__.py", line 1859, in cpu_freq
    ret = _psplatform.cpu_freq()
  File "/opt/homebrew/Cellar/bpytop/1.0.68/libexec/lib/python3.10/site-packages/psutil/_psosx.py", line 180, in cpu_freq
    curr, min_, max_ = cext.cpu_freq()
FileNotFoundError: [Errno 2] No such file or directory (originated from sysctlbyname('hw.cpufrequency'))
03/11/23 (03:10:50) | ERROR: Exception while getting cpu frequency!
03/11/23 (03:10:50) | ERROR: [Errno 2] No such file or directory (originated from sysctlbyname('hw.cpufrequency'))
Traceback (most recent call last):
  File "/opt/homebrew/bin/bpytop", line 3080, in _collect
    if CONFIG.show_cpu_freq and hasattr(psutil.cpu_freq(), "current"):
  File "/opt/homebrew/Cellar/bpytop/1.0.68/libexec/lib/python3.10/site-packages/psutil/__init__.py", line 1859, in cpu_freq
    ret = _psplatform.cpu_freq()
  File "/opt/homebrew/Cellar/bpytop/1.0.68/libexec/lib/python3.10/site-packages/psutil/_psosx.py", line 180, in cpu_freq
    curr, min_, max_ = cext.cpu_freq()
FileNotFoundError: [Errno 2] No such file or directory (originated from sysctlbyname('hw.cpufrequency'))
03/11/23 (03:12:49) | ERROR: Exception when sending signal 9 to pid 654
03/11/23 (03:12:49) | ERROR: [Errno 1] Operation not permitted
Traceback (most recent call last):
  File "/opt/homebrew/bin/bpytop", line 5479, in process_keys
    os.kill(pid, sig)
PermissionError: [Errno 1] Operation not permitted
03/11/23 (03:13:03) | ERROR: Exception when sending signal 9 to pid 654
03/11/23 (03:13:03) | ERROR: [Errno 1] Operation not permitted
Traceback (most recent call last):
  File "/opt/homebrew/bin/bpytop", line 5479, in process_keys
    os.kill(pid, sig)
PermissionError: [Errno 1] Operation not permitted
03/11/23 (03:13:17) | ERROR: Exception when sending signal 9 to pid 654
03/11/23 (03:13:17) | ERROR: [Errno 1] Operation not permitted
Traceback (most recent call last):
  File "/opt/homebrew/bin/bpytop", line 5479, in process_keys
    os.kill(pid, sig)
PermissionError: [Errno 1] Operation not permitted
03/11/23 (03:14:01) | ERROR: Exception when sending signal 2 to pid 654
03/11/23 (03:14:01) | ERROR: [Errno 1] Operation not permitted
Traceback (most recent call last):
  File "/opt/homebrew/bin/bpytop", line 5479, in process_keys
    os.kill(pid, sig)
PermissionError: [Errno 1] Operation not permitted
03/11/23 (03:14:22) | ERROR: Exception when sending signal 15 to pid 654
03/11/23 (03:14:22) | ERROR: [Errno 1] Operation not permitted
Traceback (most recent call last):
  File "/opt/homebrew/bin/bpytop", line 5479, in process_keys
    os.kill(pid, sig)
PermissionError: [Errno 1] Operation not permitted
03/11/23 (03:14:26) | ERROR: Exception when sending signal 15 to pid 654
03/11/23 (03:14:26) | ERROR: [Errno 1] Operation not permitted
Traceback (most recent call last):
  File "/opt/homebrew/bin/bpytop", line 5479, in process_keys
    os.kill(pid, sig)
PermissionError: [Errno 1] Operation not permitted
31/12/23 (23:37:54) | ERROR: Exception while getting cpu frequency!
31/12/23 (23:37:54) | ERROR: [Errno 2] No such file or directory (originated from sysctlbyname('hw.cpufrequency'))
Traceback (most recent call last):
  File "/opt/homebrew/bin/bpytop", line 3080, in _collect
    if CONFIG.show_cpu_freq and hasattr(psutil.cpu_freq(), "current"):
  File "/opt/homebrew/Cellar/bpytop/1.0.68/libexec/lib/python3.10/site-packages/psutil/__init__.py", line 1859, in cpu_freq
    ret = _psplatform.cpu_freq()
  File "/opt/homebrew/Cellar/bpytop/1.0.68/libexec/lib/python3.10/site-packages/psutil/_psosx.py", line 180, in cpu_freq
    curr, min_, max_ = cext.cpu_freq()
FileNotFoundError: [Errno 2] No such file or directory (originated from sysctlbyname('hw.cpufrequency'))
08/03/24 (17:08:07) | ERROR: Exception while getting cpu frequency!
08/03/24 (17:08:07) | ERROR: [Errno 2] No such file or directory (originated from sysctlbyname('hw.cpufrequency'))
Traceback (most recent call last):
  File "/opt/homebrew/bin/bpytop", line 3080, in _collect
    if CONFIG.show_cpu_freq and hasattr(psutil.cpu_freq(), "current"):
  File "/opt/homebrew/Cellar/bpytop/1.0.68/libexec/lib/python3.10/site-packages/psutil/__init__.py", line 1859, in cpu_freq
    ret = _psplatform.cpu_freq()
  File "/opt/homebrew/Cellar/bpytop/1.0.68/libexec/lib/python3.10/site-packages/psutil/_psosx.py", line 180, in cpu_freq
    curr, min_, max_ = cext.cpu_freq()
FileNotFoundError: [Errno 2] No such file or directory (originated from sysctlbyname('hw.cpufrequency'))
06/05/24 (23:42:18) | ERROR: Exception while getting cpu frequency!
06/05/24 (23:42:18) | ERROR: [Errno 2] No such file or directory (originated from sysctlbyname('hw.cpufrequency'))
Traceback (most recent call last):
  File "/opt/homebrew/bin/bpytop", line 3080, in _collect
    if CONFIG.show_cpu_freq and hasattr(psutil.cpu_freq(), "current"):
  File "/opt/homebrew/Cellar/bpytop/1.0.68/libexec/lib/python3.10/site-packages/psutil/__init__.py", line 1859, in cpu_freq
    ret = _psplatform.cpu_freq()
  File "/opt/homebrew/Cellar/bpytop/1.0.68/libexec/lib/python3.10/site-packages/psutil/_psosx.py", line 180, in cpu_freq
    curr, min_, max_ = cext.cpu_freq()
FileNotFoundError: [Errno 2] No such file or directory (originated from sysctlbyname('hw.cpufrequency'))
26/05/24 (01:03:32) | ERROR: Exception while getting cpu frequency!
26/05/24 (01:03:32) | ERROR: [Errno 2] No such file or directory (originated from sysctlbyname('hw.cpufrequency'))
Traceback (most recent call last):
  File "/opt/homebrew/bin/bpytop", line 3080, in _collect
    if CONFIG.show_cpu_freq and hasattr(psutil.cpu_freq(), "current"):
  File "/opt/homebrew/Cellar/bpytop/1.0.68/libexec/lib/python3.10/site-packages/psutil/__init__.py", line 1859, in cpu_freq
    ret = _psplatform.cpu_freq()
  File "/opt/homebrew/Cellar/bpytop/1.0.68/libexec/lib/python3.10/site-packages/psutil/_psosx.py", line 180, in cpu_freq
    curr, min_, max_ = cext.cpu_freq()
FileNotFoundError: [Errno 2] No such file or directory (originated from sysctlbyname('hw.cpufrequency'))
